{
 "cells": [
  {
   "cell_type": "code",
   "execution_count": 1,
   "metadata": {},
   "outputs": [
    {
     "name": "stderr",
     "output_type": "stream",
     "text": [
      "\n",
      "A module that was compiled using NumPy 1.x cannot be run in\n",
      "NumPy 2.1.3 as it may crash. To support both 1.x and 2.x\n",
      "versions of NumPy, modules must be compiled with NumPy 2.0.\n",
      "Some module may need to rebuild instead e.g. with 'pybind11>=2.12'.\n",
      "\n",
      "If you are a user of the module, the easiest solution will be to\n",
      "downgrade to 'numpy<2' or try to upgrade the affected module.\n",
      "We expect that some modules will need time to support NumPy 2.\n",
      "\n",
      "Traceback (most recent call last):  File \"<frozen runpy>\", line 198, in _run_module_as_main\n",
      "  File \"<frozen runpy>\", line 88, in _run_code\n",
      "  File \"c:\\Users\\user\\anaconda3\\Lib\\site-packages\\ipykernel_launcher.py\", line 17, in <module>\n",
      "    app.launch_new_instance()\n",
      "  File \"c:\\Users\\user\\anaconda3\\Lib\\site-packages\\traitlets\\config\\application.py\", line 1075, in launch_instance\n",
      "    app.start()\n",
      "  File \"c:\\Users\\user\\anaconda3\\Lib\\site-packages\\ipykernel\\kernelapp.py\", line 701, in start\n",
      "    self.io_loop.start()\n",
      "  File \"c:\\Users\\user\\anaconda3\\Lib\\site-packages\\tornado\\platform\\asyncio.py\", line 195, in start\n",
      "    self.asyncio_loop.run_forever()\n",
      "  File \"c:\\Users\\user\\anaconda3\\Lib\\asyncio\\windows_events.py\", line 321, in run_forever\n",
      "    super().run_forever()\n",
      "  File \"c:\\Users\\user\\anaconda3\\Lib\\asyncio\\base_events.py\", line 607, in run_forever\n",
      "    self._run_once()\n",
      "  File \"c:\\Users\\user\\anaconda3\\Lib\\asyncio\\base_events.py\", line 1922, in _run_once\n",
      "    handle._run()\n",
      "  File \"c:\\Users\\user\\anaconda3\\Lib\\asyncio\\events.py\", line 80, in _run\n",
      "    self._context.run(self._callback, *self._args)\n",
      "  File \"c:\\Users\\user\\anaconda3\\Lib\\site-packages\\ipykernel\\kernelbase.py\", line 534, in dispatch_queue\n",
      "    await self.process_one()\n",
      "  File \"c:\\Users\\user\\anaconda3\\Lib\\site-packages\\ipykernel\\kernelbase.py\", line 523, in process_one\n",
      "    await dispatch(*args)\n",
      "  File \"c:\\Users\\user\\anaconda3\\Lib\\site-packages\\ipykernel\\kernelbase.py\", line 429, in dispatch_shell\n",
      "    await result\n",
      "  File \"c:\\Users\\user\\anaconda3\\Lib\\site-packages\\ipykernel\\kernelbase.py\", line 767, in execute_request\n",
      "    reply_content = await reply_content\n",
      "  File \"c:\\Users\\user\\anaconda3\\Lib\\site-packages\\ipykernel\\ipkernel.py\", line 429, in do_execute\n",
      "    res = shell.run_cell(\n",
      "  File \"c:\\Users\\user\\anaconda3\\Lib\\site-packages\\ipykernel\\zmqshell.py\", line 549, in run_cell\n",
      "    return super().run_cell(*args, **kwargs)\n",
      "  File \"c:\\Users\\user\\anaconda3\\Lib\\site-packages\\IPython\\core\\interactiveshell.py\", line 3075, in run_cell\n",
      "    result = self._run_cell(\n",
      "  File \"c:\\Users\\user\\anaconda3\\Lib\\site-packages\\IPython\\core\\interactiveshell.py\", line 3130, in _run_cell\n",
      "    result = runner(coro)\n",
      "  File \"c:\\Users\\user\\anaconda3\\Lib\\site-packages\\IPython\\core\\async_helpers.py\", line 128, in _pseudo_sync_runner\n",
      "    coro.send(None)\n",
      "  File \"c:\\Users\\user\\anaconda3\\Lib\\site-packages\\IPython\\core\\interactiveshell.py\", line 3334, in run_cell_async\n",
      "    has_raised = await self.run_ast_nodes(code_ast.body, cell_name,\n",
      "  File \"c:\\Users\\user\\anaconda3\\Lib\\site-packages\\IPython\\core\\interactiveshell.py\", line 3517, in run_ast_nodes\n",
      "    if await self.run_code(code, result, async_=asy):\n",
      "  File \"c:\\Users\\user\\anaconda3\\Lib\\site-packages\\IPython\\core\\interactiveshell.py\", line 3577, in run_code\n",
      "    exec(code_obj, self.user_global_ns, self.user_ns)\n",
      "  File \"C:\\Users\\user\\AppData\\Local\\Temp\\ipykernel_132996\\1837368436.py\", line 5, in <module>\n",
      "    import pandas as pd\n",
      "  File \"c:\\Users\\user\\anaconda3\\Lib\\site-packages\\pandas\\__init__.py\", line 39, in <module>\n",
      "    from pandas.compat import (\n",
      "  File \"c:\\Users\\user\\anaconda3\\Lib\\site-packages\\pandas\\compat\\__init__.py\", line 27, in <module>\n",
      "    from pandas.compat.pyarrow import (\n",
      "  File \"c:\\Users\\user\\anaconda3\\Lib\\site-packages\\pandas\\compat\\pyarrow.py\", line 8, in <module>\n",
      "    import pyarrow as pa\n",
      "  File \"c:\\Users\\user\\anaconda3\\Lib\\site-packages\\pyarrow\\__init__.py\", line 65, in <module>\n",
      "    import pyarrow.lib as _lib\n"
     ]
    },
    {
     "ename": "AttributeError",
     "evalue": "_ARRAY_API not found",
     "output_type": "error",
     "traceback": [
      "\u001b[1;31m---------------------------------------------------------------------------\u001b[0m",
      "\u001b[1;31mAttributeError\u001b[0m                            Traceback (most recent call last)",
      "\u001b[1;31mAttributeError\u001b[0m: _ARRAY_API not found"
     ]
    },
    {
     "name": "stderr",
     "output_type": "stream",
     "text": [
      "\n",
      "A module that was compiled using NumPy 1.x cannot be run in\n",
      "NumPy 2.1.3 as it may crash. To support both 1.x and 2.x\n",
      "versions of NumPy, modules must be compiled with NumPy 2.0.\n",
      "Some module may need to rebuild instead e.g. with 'pybind11>=2.12'.\n",
      "\n",
      "If you are a user of the module, the easiest solution will be to\n",
      "downgrade to 'numpy<2' or try to upgrade the affected module.\n",
      "We expect that some modules will need time to support NumPy 2.\n",
      "\n",
      "Traceback (most recent call last):  File \"<frozen runpy>\", line 198, in _run_module_as_main\n",
      "  File \"<frozen runpy>\", line 88, in _run_code\n",
      "  File \"c:\\Users\\user\\anaconda3\\Lib\\site-packages\\ipykernel_launcher.py\", line 17, in <module>\n",
      "    app.launch_new_instance()\n",
      "  File \"c:\\Users\\user\\anaconda3\\Lib\\site-packages\\traitlets\\config\\application.py\", line 1075, in launch_instance\n",
      "    app.start()\n",
      "  File \"c:\\Users\\user\\anaconda3\\Lib\\site-packages\\ipykernel\\kernelapp.py\", line 701, in start\n",
      "    self.io_loop.start()\n",
      "  File \"c:\\Users\\user\\anaconda3\\Lib\\site-packages\\tornado\\platform\\asyncio.py\", line 195, in start\n",
      "    self.asyncio_loop.run_forever()\n",
      "  File \"c:\\Users\\user\\anaconda3\\Lib\\asyncio\\windows_events.py\", line 321, in run_forever\n",
      "    super().run_forever()\n",
      "  File \"c:\\Users\\user\\anaconda3\\Lib\\asyncio\\base_events.py\", line 607, in run_forever\n",
      "    self._run_once()\n",
      "  File \"c:\\Users\\user\\anaconda3\\Lib\\asyncio\\base_events.py\", line 1922, in _run_once\n",
      "    handle._run()\n",
      "  File \"c:\\Users\\user\\anaconda3\\Lib\\asyncio\\events.py\", line 80, in _run\n",
      "    self._context.run(self._callback, *self._args)\n",
      "  File \"c:\\Users\\user\\anaconda3\\Lib\\site-packages\\ipykernel\\kernelbase.py\", line 534, in dispatch_queue\n",
      "    await self.process_one()\n",
      "  File \"c:\\Users\\user\\anaconda3\\Lib\\site-packages\\ipykernel\\kernelbase.py\", line 523, in process_one\n",
      "    await dispatch(*args)\n",
      "  File \"c:\\Users\\user\\anaconda3\\Lib\\site-packages\\ipykernel\\kernelbase.py\", line 429, in dispatch_shell\n",
      "    await result\n",
      "  File \"c:\\Users\\user\\anaconda3\\Lib\\site-packages\\ipykernel\\kernelbase.py\", line 767, in execute_request\n",
      "    reply_content = await reply_content\n",
      "  File \"c:\\Users\\user\\anaconda3\\Lib\\site-packages\\ipykernel\\ipkernel.py\", line 429, in do_execute\n",
      "    res = shell.run_cell(\n",
      "  File \"c:\\Users\\user\\anaconda3\\Lib\\site-packages\\ipykernel\\zmqshell.py\", line 549, in run_cell\n",
      "    return super().run_cell(*args, **kwargs)\n",
      "  File \"c:\\Users\\user\\anaconda3\\Lib\\site-packages\\IPython\\core\\interactiveshell.py\", line 3075, in run_cell\n",
      "    result = self._run_cell(\n",
      "  File \"c:\\Users\\user\\anaconda3\\Lib\\site-packages\\IPython\\core\\interactiveshell.py\", line 3130, in _run_cell\n",
      "    result = runner(coro)\n",
      "  File \"c:\\Users\\user\\anaconda3\\Lib\\site-packages\\IPython\\core\\async_helpers.py\", line 128, in _pseudo_sync_runner\n",
      "    coro.send(None)\n",
      "  File \"c:\\Users\\user\\anaconda3\\Lib\\site-packages\\IPython\\core\\interactiveshell.py\", line 3334, in run_cell_async\n",
      "    has_raised = await self.run_ast_nodes(code_ast.body, cell_name,\n",
      "  File \"c:\\Users\\user\\anaconda3\\Lib\\site-packages\\IPython\\core\\interactiveshell.py\", line 3517, in run_ast_nodes\n",
      "    if await self.run_code(code, result, async_=asy):\n",
      "  File \"c:\\Users\\user\\anaconda3\\Lib\\site-packages\\IPython\\core\\interactiveshell.py\", line 3577, in run_code\n",
      "    exec(code_obj, self.user_global_ns, self.user_ns)\n",
      "  File \"C:\\Users\\user\\AppData\\Local\\Temp\\ipykernel_132996\\1837368436.py\", line 5, in <module>\n",
      "    import pandas as pd\n",
      "  File \"c:\\Users\\user\\anaconda3\\Lib\\site-packages\\pandas\\__init__.py\", line 62, in <module>\n",
      "    from pandas.core.api import (\n",
      "  File \"c:\\Users\\user\\anaconda3\\Lib\\site-packages\\pandas\\core\\api.py\", line 9, in <module>\n",
      "    from pandas.core.dtypes.dtypes import (\n",
      "  File \"c:\\Users\\user\\anaconda3\\Lib\\site-packages\\pandas\\core\\dtypes\\dtypes.py\", line 24, in <module>\n",
      "    from pandas._libs import (\n",
      "  File \"c:\\Users\\user\\anaconda3\\Lib\\site-packages\\pyarrow\\__init__.py\", line 65, in <module>\n",
      "    import pyarrow.lib as _lib\n"
     ]
    },
    {
     "ename": "AttributeError",
     "evalue": "_ARRAY_API not found",
     "output_type": "error",
     "traceback": [
      "\u001b[1;31m---------------------------------------------------------------------------\u001b[0m",
      "\u001b[1;31mAttributeError\u001b[0m                            Traceback (most recent call last)",
      "\u001b[1;31mAttributeError\u001b[0m: _ARRAY_API not found"
     ]
    },
    {
     "name": "stderr",
     "output_type": "stream",
     "text": [
      "\n",
      "A module that was compiled using NumPy 1.x cannot be run in\n",
      "NumPy 2.1.3 as it may crash. To support both 1.x and 2.x\n",
      "versions of NumPy, modules must be compiled with NumPy 2.0.\n",
      "Some module may need to rebuild instead e.g. with 'pybind11>=2.12'.\n",
      "\n",
      "If you are a user of the module, the easiest solution will be to\n",
      "downgrade to 'numpy<2' or try to upgrade the affected module.\n",
      "We expect that some modules will need time to support NumPy 2.\n",
      "\n",
      "Traceback (most recent call last):  File \"<frozen runpy>\", line 198, in _run_module_as_main\n",
      "  File \"<frozen runpy>\", line 88, in _run_code\n",
      "  File \"c:\\Users\\user\\anaconda3\\Lib\\site-packages\\ipykernel_launcher.py\", line 17, in <module>\n",
      "    app.launch_new_instance()\n",
      "  File \"c:\\Users\\user\\anaconda3\\Lib\\site-packages\\traitlets\\config\\application.py\", line 1075, in launch_instance\n",
      "    app.start()\n",
      "  File \"c:\\Users\\user\\anaconda3\\Lib\\site-packages\\ipykernel\\kernelapp.py\", line 701, in start\n",
      "    self.io_loop.start()\n",
      "  File \"c:\\Users\\user\\anaconda3\\Lib\\site-packages\\tornado\\platform\\asyncio.py\", line 195, in start\n",
      "    self.asyncio_loop.run_forever()\n",
      "  File \"c:\\Users\\user\\anaconda3\\Lib\\asyncio\\windows_events.py\", line 321, in run_forever\n",
      "    super().run_forever()\n",
      "  File \"c:\\Users\\user\\anaconda3\\Lib\\asyncio\\base_events.py\", line 607, in run_forever\n",
      "    self._run_once()\n",
      "  File \"c:\\Users\\user\\anaconda3\\Lib\\asyncio\\base_events.py\", line 1922, in _run_once\n",
      "    handle._run()\n",
      "  File \"c:\\Users\\user\\anaconda3\\Lib\\asyncio\\events.py\", line 80, in _run\n",
      "    self._context.run(self._callback, *self._args)\n",
      "  File \"c:\\Users\\user\\anaconda3\\Lib\\site-packages\\ipykernel\\kernelbase.py\", line 534, in dispatch_queue\n",
      "    await self.process_one()\n",
      "  File \"c:\\Users\\user\\anaconda3\\Lib\\site-packages\\ipykernel\\kernelbase.py\", line 523, in process_one\n",
      "    await dispatch(*args)\n",
      "  File \"c:\\Users\\user\\anaconda3\\Lib\\site-packages\\ipykernel\\kernelbase.py\", line 429, in dispatch_shell\n",
      "    await result\n",
      "  File \"c:\\Users\\user\\anaconda3\\Lib\\site-packages\\ipykernel\\kernelbase.py\", line 767, in execute_request\n",
      "    reply_content = await reply_content\n",
      "  File \"c:\\Users\\user\\anaconda3\\Lib\\site-packages\\ipykernel\\ipkernel.py\", line 429, in do_execute\n",
      "    res = shell.run_cell(\n",
      "  File \"c:\\Users\\user\\anaconda3\\Lib\\site-packages\\ipykernel\\zmqshell.py\", line 549, in run_cell\n",
      "    return super().run_cell(*args, **kwargs)\n",
      "  File \"c:\\Users\\user\\anaconda3\\Lib\\site-packages\\IPython\\core\\interactiveshell.py\", line 3075, in run_cell\n",
      "    result = self._run_cell(\n",
      "  File \"c:\\Users\\user\\anaconda3\\Lib\\site-packages\\IPython\\core\\interactiveshell.py\", line 3130, in _run_cell\n",
      "    result = runner(coro)\n",
      "  File \"c:\\Users\\user\\anaconda3\\Lib\\site-packages\\IPython\\core\\async_helpers.py\", line 128, in _pseudo_sync_runner\n",
      "    coro.send(None)\n",
      "  File \"c:\\Users\\user\\anaconda3\\Lib\\site-packages\\IPython\\core\\interactiveshell.py\", line 3334, in run_cell_async\n",
      "    has_raised = await self.run_ast_nodes(code_ast.body, cell_name,\n",
      "  File \"c:\\Users\\user\\anaconda3\\Lib\\site-packages\\IPython\\core\\interactiveshell.py\", line 3517, in run_ast_nodes\n",
      "    if await self.run_code(code, result, async_=asy):\n",
      "  File \"c:\\Users\\user\\anaconda3\\Lib\\site-packages\\IPython\\core\\interactiveshell.py\", line 3577, in run_code\n",
      "    exec(code_obj, self.user_global_ns, self.user_ns)\n",
      "  File \"C:\\Users\\user\\AppData\\Local\\Temp\\ipykernel_132996\\1837368436.py\", line 5, in <module>\n",
      "    import pandas as pd\n",
      "  File \"c:\\Users\\user\\anaconda3\\Lib\\site-packages\\pandas\\__init__.py\", line 62, in <module>\n",
      "    from pandas.core.api import (\n",
      "  File \"c:\\Users\\user\\anaconda3\\Lib\\site-packages\\pandas\\core\\api.py\", line 28, in <module>\n",
      "    from pandas.core.arrays import Categorical\n",
      "  File \"c:\\Users\\user\\anaconda3\\Lib\\site-packages\\pandas\\core\\arrays\\__init__.py\", line 1, in <module>\n",
      "    from pandas.core.arrays.arrow import ArrowExtensionArray\n",
      "  File \"c:\\Users\\user\\anaconda3\\Lib\\site-packages\\pandas\\core\\arrays\\arrow\\__init__.py\", line 5, in <module>\n",
      "    from pandas.core.arrays.arrow.array import ArrowExtensionArray\n",
      "  File \"c:\\Users\\user\\anaconda3\\Lib\\site-packages\\pandas\\core\\arrays\\arrow\\array.py\", line 50, in <module>\n",
      "    from pandas.core import (\n",
      "  File \"c:\\Users\\user\\anaconda3\\Lib\\site-packages\\pandas\\core\\ops\\__init__.py\", line 8, in <module>\n",
      "    from pandas.core.ops.array_ops import (\n",
      "  File \"c:\\Users\\user\\anaconda3\\Lib\\site-packages\\pandas\\core\\ops\\array_ops.py\", line 56, in <module>\n",
      "    from pandas.core.computation import expressions\n",
      "  File \"c:\\Users\\user\\anaconda3\\Lib\\site-packages\\pandas\\core\\computation\\expressions.py\", line 21, in <module>\n",
      "    from pandas.core.computation.check import NUMEXPR_INSTALLED\n",
      "  File \"c:\\Users\\user\\anaconda3\\Lib\\site-packages\\pandas\\core\\computation\\check.py\", line 5, in <module>\n",
      "    ne = import_optional_dependency(\"numexpr\", errors=\"warn\")\n",
      "  File \"c:\\Users\\user\\anaconda3\\Lib\\site-packages\\pandas\\compat\\_optional.py\", line 135, in import_optional_dependency\n",
      "    module = importlib.import_module(name)\n",
      "  File \"c:\\Users\\user\\anaconda3\\Lib\\importlib\\__init__.py\", line 126, in import_module\n",
      "    return _bootstrap._gcd_import(name[level:], package, level)\n",
      "  File \"c:\\Users\\user\\anaconda3\\Lib\\site-packages\\numexpr\\__init__.py\", line 24, in <module>\n",
      "    from numexpr.interpreter import MAX_THREADS, use_vml, __BLOCK_SIZE1__\n"
     ]
    },
    {
     "ename": "AttributeError",
     "evalue": "_ARRAY_API not found",
     "output_type": "error",
     "traceback": [
      "\u001b[1;31m---------------------------------------------------------------------------\u001b[0m",
      "\u001b[1;31mAttributeError\u001b[0m                            Traceback (most recent call last)",
      "\u001b[1;31mAttributeError\u001b[0m: _ARRAY_API not found"
     ]
    },
    {
     "name": "stderr",
     "output_type": "stream",
     "text": [
      "\n",
      "A module that was compiled using NumPy 1.x cannot be run in\n",
      "NumPy 2.1.3 as it may crash. To support both 1.x and 2.x\n",
      "versions of NumPy, modules must be compiled with NumPy 2.0.\n",
      "Some module may need to rebuild instead e.g. with 'pybind11>=2.12'.\n",
      "\n",
      "If you are a user of the module, the easiest solution will be to\n",
      "downgrade to 'numpy<2' or try to upgrade the affected module.\n",
      "We expect that some modules will need time to support NumPy 2.\n",
      "\n",
      "Traceback (most recent call last):  File \"<frozen runpy>\", line 198, in _run_module_as_main\n",
      "  File \"<frozen runpy>\", line 88, in _run_code\n",
      "  File \"c:\\Users\\user\\anaconda3\\Lib\\site-packages\\ipykernel_launcher.py\", line 17, in <module>\n",
      "    app.launch_new_instance()\n",
      "  File \"c:\\Users\\user\\anaconda3\\Lib\\site-packages\\traitlets\\config\\application.py\", line 1075, in launch_instance\n",
      "    app.start()\n",
      "  File \"c:\\Users\\user\\anaconda3\\Lib\\site-packages\\ipykernel\\kernelapp.py\", line 701, in start\n",
      "    self.io_loop.start()\n",
      "  File \"c:\\Users\\user\\anaconda3\\Lib\\site-packages\\tornado\\platform\\asyncio.py\", line 195, in start\n",
      "    self.asyncio_loop.run_forever()\n",
      "  File \"c:\\Users\\user\\anaconda3\\Lib\\asyncio\\windows_events.py\", line 321, in run_forever\n",
      "    super().run_forever()\n",
      "  File \"c:\\Users\\user\\anaconda3\\Lib\\asyncio\\base_events.py\", line 607, in run_forever\n",
      "    self._run_once()\n",
      "  File \"c:\\Users\\user\\anaconda3\\Lib\\asyncio\\base_events.py\", line 1922, in _run_once\n",
      "    handle._run()\n",
      "  File \"c:\\Users\\user\\anaconda3\\Lib\\asyncio\\events.py\", line 80, in _run\n",
      "    self._context.run(self._callback, *self._args)\n",
      "  File \"c:\\Users\\user\\anaconda3\\Lib\\site-packages\\ipykernel\\kernelbase.py\", line 534, in dispatch_queue\n",
      "    await self.process_one()\n",
      "  File \"c:\\Users\\user\\anaconda3\\Lib\\site-packages\\ipykernel\\kernelbase.py\", line 523, in process_one\n",
      "    await dispatch(*args)\n",
      "  File \"c:\\Users\\user\\anaconda3\\Lib\\site-packages\\ipykernel\\kernelbase.py\", line 429, in dispatch_shell\n",
      "    await result\n",
      "  File \"c:\\Users\\user\\anaconda3\\Lib\\site-packages\\ipykernel\\kernelbase.py\", line 767, in execute_request\n",
      "    reply_content = await reply_content\n",
      "  File \"c:\\Users\\user\\anaconda3\\Lib\\site-packages\\ipykernel\\ipkernel.py\", line 429, in do_execute\n",
      "    res = shell.run_cell(\n",
      "  File \"c:\\Users\\user\\anaconda3\\Lib\\site-packages\\ipykernel\\zmqshell.py\", line 549, in run_cell\n",
      "    return super().run_cell(*args, **kwargs)\n",
      "  File \"c:\\Users\\user\\anaconda3\\Lib\\site-packages\\IPython\\core\\interactiveshell.py\", line 3075, in run_cell\n",
      "    result = self._run_cell(\n",
      "  File \"c:\\Users\\user\\anaconda3\\Lib\\site-packages\\IPython\\core\\interactiveshell.py\", line 3130, in _run_cell\n",
      "    result = runner(coro)\n",
      "  File \"c:\\Users\\user\\anaconda3\\Lib\\site-packages\\IPython\\core\\async_helpers.py\", line 128, in _pseudo_sync_runner\n",
      "    coro.send(None)\n",
      "  File \"c:\\Users\\user\\anaconda3\\Lib\\site-packages\\IPython\\core\\interactiveshell.py\", line 3334, in run_cell_async\n",
      "    has_raised = await self.run_ast_nodes(code_ast.body, cell_name,\n",
      "  File \"c:\\Users\\user\\anaconda3\\Lib\\site-packages\\IPython\\core\\interactiveshell.py\", line 3517, in run_ast_nodes\n",
      "    if await self.run_code(code, result, async_=asy):\n",
      "  File \"c:\\Users\\user\\anaconda3\\Lib\\site-packages\\IPython\\core\\interactiveshell.py\", line 3577, in run_code\n",
      "    exec(code_obj, self.user_global_ns, self.user_ns)\n",
      "  File \"C:\\Users\\user\\AppData\\Local\\Temp\\ipykernel_132996\\1837368436.py\", line 5, in <module>\n",
      "    import pandas as pd\n",
      "  File \"c:\\Users\\user\\anaconda3\\Lib\\site-packages\\pandas\\__init__.py\", line 62, in <module>\n",
      "    from pandas.core.api import (\n",
      "  File \"c:\\Users\\user\\anaconda3\\Lib\\site-packages\\pandas\\core\\api.py\", line 28, in <module>\n",
      "    from pandas.core.arrays import Categorical\n",
      "  File \"c:\\Users\\user\\anaconda3\\Lib\\site-packages\\pandas\\core\\arrays\\__init__.py\", line 1, in <module>\n",
      "    from pandas.core.arrays.arrow import ArrowExtensionArray\n",
      "  File \"c:\\Users\\user\\anaconda3\\Lib\\site-packages\\pandas\\core\\arrays\\arrow\\__init__.py\", line 5, in <module>\n",
      "    from pandas.core.arrays.arrow.array import ArrowExtensionArray\n",
      "  File \"c:\\Users\\user\\anaconda3\\Lib\\site-packages\\pandas\\core\\arrays\\arrow\\array.py\", line 64, in <module>\n",
      "    from pandas.core.arrays.masked import BaseMaskedArray\n",
      "  File \"c:\\Users\\user\\anaconda3\\Lib\\site-packages\\pandas\\core\\arrays\\masked.py\", line 60, in <module>\n",
      "    from pandas.core import (\n",
      "  File \"c:\\Users\\user\\anaconda3\\Lib\\site-packages\\pandas\\core\\nanops.py\", line 52, in <module>\n",
      "    bn = import_optional_dependency(\"bottleneck\", errors=\"warn\")\n",
      "  File \"c:\\Users\\user\\anaconda3\\Lib\\site-packages\\pandas\\compat\\_optional.py\", line 135, in import_optional_dependency\n",
      "    module = importlib.import_module(name)\n",
      "  File \"c:\\Users\\user\\anaconda3\\Lib\\importlib\\__init__.py\", line 126, in import_module\n",
      "    return _bootstrap._gcd_import(name[level:], package, level)\n",
      "  File \"c:\\Users\\user\\anaconda3\\Lib\\site-packages\\bottleneck\\__init__.py\", line 7, in <module>\n",
      "    from .move import (move_argmax, move_argmin, move_max, move_mean, move_median,\n"
     ]
    },
    {
     "ename": "AttributeError",
     "evalue": "_ARRAY_API not found",
     "output_type": "error",
     "traceback": [
      "\u001b[1;31m---------------------------------------------------------------------------\u001b[0m",
      "\u001b[1;31mAttributeError\u001b[0m                            Traceback (most recent call last)",
      "\u001b[1;31mAttributeError\u001b[0m: _ARRAY_API not found"
     ]
    }
   ],
   "source": [
    "import sys\n",
    "import os\n",
    "import glob\n",
    "import time\n",
    "import pandas as pd\n",
    "import ast\n",
    "\n",
    "sys.path.append('..')\n",
    "import constants.constants as const\n",
    "import constants.file_handler_constants as fh\n",
    "from constants.restaurant_constants import *\n",
    "\n",
    "from packages.restaurant.Restaurant import *\n",
    "from packages.file_handler_package.file_handler import *"
   ]
  },
  {
   "cell_type": "code",
   "execution_count": 2,
   "metadata": {},
   "outputs": [],
   "source": [
    "def map_type_tripAdvisor_to_wongnai(type: list[str], website:str) -> list[str]:\n",
    "    \n",
    "    if(\"tripadvisor.com\" not in website):\n",
    "        return\n",
    "\n",
    "    res_type = []\n",
    "    for cur_type in type:\n",
    "        find_type = TYPE_TRIPADVISOR_TO_WONGNAI_MAPPER.get(cur_type, 0)\n",
    "        if(find_type and find_type not in res_type):\n",
    "            res_type.append(find_type)\n",
    "    \n",
    "    return res_type.copy()"
   ]
  },
  {
   "cell_type": "code",
   "execution_count": 3,
   "metadata": {},
   "outputs": [
    {
     "name": "stdout",
     "output_type": "stream",
     "text": [
      "Directory res_merge_restaurant created successfully\n"
     ]
    }
   ],
   "source": [
    "# this module is use for merge dataframe of all page in selected province from 'mulProcess_restaurant_scraping_proxy'\n",
    "\n",
    "# ** select a province by index of 'ALL_RESTAURANTS_TRIPADVISOR_DATA' (manually)\n",
    "Idx_of_region = 0\n",
    "cur_region_data = ALL_RESTAURANTS_TRIPADVISOR_DATA[Idx_of_region]\n",
    "\n",
    "#\n",
    "cur_province_en = cur_region_data[0]\n",
    "\n",
    "all_res_scraping_province = glob.glob(os.path.join(fh.STORE_RESTAURANT_SCRAPING, \"res_restaurant_scraping\", 'res_restaurant_%s' % (cur_province_en), '*.csv'))\n",
    "\n",
    "res_merge_df = pd.DataFrame()\n",
    "for cur_page_path in all_res_scraping_province:\n",
    "    cur_page_df = pd.read_csv(cur_page_path)\n",
    "    res_merge_df = pd.concat([res_merge_df, cur_page_df])\n",
    "\n",
    "# remove duplicate attraction \n",
    "res_merge_df.drop_duplicates(subset=['name'], inplace=True)\n",
    "# remove row with missing latitude\n",
    "# Drop rows with 'latitude' or 'longitude' equal to 0\n",
    "res_merge_df = res_merge_df[(res_merge_df['latitude'] != 0) & (res_merge_df['longitude'] != 0)]\n",
    "res_merge_df = res_merge_df[(res_merge_df['latitude'].notnull()) & (res_merge_df['longitude'].notnull())]\n",
    "\n",
    "# map type from tripadvisor to wongnai\n",
    "res_merge_df['type'] = res_merge_df.apply(lambda x: map_type_tripAdvisor_to_wongnai(\n",
    "    type = ast.literal_eval(x['type']),\n",
    "    website = x['website']\n",
    "), axis=1)\n",
    "\n",
    "# set new index\n",
    "res_merge_df.set_index(['name'], inplace=True)\n",
    "\n",
    "# create directory to store result of merging restaurant by a province\n",
    "createDirectory(fh.STORE_MERGE_RESTAURANT_SCRAPING, 'res_merge_restaurant')\n",
    "\n",
    "# save result dataframe to .csv \n",
    "# for example: 'res_restaurant_Mukdahan_page_1_44.csv'\n",
    "res_file_name = 'res_merge_restaurant_%s.csv' % (cur_province_en)\n",
    "res_path = os.path.join(fh.STORE_MERGE_RESTAURANT_SCRAPING, 'res_merge_restaurant', res_file_name) \n",
    "res_merge_df.to_csv(res_path, encoding=\"utf-8\")\n"
   ]
  },
  {
   "cell_type": "code",
   "execution_count": null,
   "metadata": {},
   "outputs": [],
   "source": []
  }
 ],
 "metadata": {
  "kernelspec": {
   "display_name": "base",
   "language": "python",
   "name": "python3"
  },
  "language_info": {
   "codemirror_mode": {
    "name": "ipython",
    "version": 3
   },
   "file_extension": ".py",
   "mimetype": "text/x-python",
   "name": "python",
   "nbconvert_exporter": "python",
   "pygments_lexer": "ipython3",
   "version": "3.11.7"
  }
 },
 "nbformat": 4,
 "nbformat_minor": 2
}
